Workbook

Sheet Footing Jacket
D1: D E S I G N S H E E T
D2: Project : | E2: Project name
D3: Member : | E3: F-1 - Grid A-1
D4: Designed / Date : | E4: Albert Pamonag | G4: =TODAY() -> 46299
D5: Checked / Date :
B6: JACKETING (ENLARGEMENT) OF AN EXISTING ISOLATED FOOTING
B7: ACI 562-25 - Assessment, Repair and Rehabilitation of Existing Concrete Structures; ACI 318-25M; ASCE 41-17
B8: Yellow cells are inputs. Every other cell is locked. Owner: Albert Pamonag - Albert Pamonag Engineering Consultancy.
B10: Description | C10: Symbol | D10: Value | E10: Unit | F10: Equation / reference | G10: Status
B12: 1.0 INPUT DATA
B32: Existing footing
B33: Existing footing width | C33: B0 | D33: 2000 | E33: mm
B34: Existing footing length | C34: L0 | D34: 3000 | E34: mm
B35: Existing footing thickness | C35: h0 | D35: 600 | E35: mm
B36: Existing concrete strength | C36: f'c0 | D36: 21 | E36: MPa
B37: Existing reinforcement yield | C37: fy0 | D37: 275 | E37: MPa
B38: Existing bottom bars parallel to L | C38: n | D38: 8 | F38: outer (lower) layer, across the width B0
B39: Their diameter | C39: db | D39: 20 | E39: mm
B40: Existing bottom bars parallel to B | C40: n | D40: 15 | F40: inner layer, across the length L0
B41: Their diameter | C41: db | D41: 20 | E41: mm
B42: Clear cover to the existing outer layer | C42: cc0 | D42: 75 | E42: mm
B43: Column
B44: Column dimension parallel to B | C44: cB | D44: 400 | E44: mm | F44: at the top of the footing (jacketed size if the column is jacketed)
B45: Column dimension parallel to L | C45: cL | D45: 400 | E45: mm
B46: Column location factor | C46: alpha_s | D46: 40 | F46: ACI 318-25M 22.6.5.3: 40 interior, 30 edge, 20 corner
B47: Overlay tied to the column? | D47: Yes | F47: No: shear uses the existing depth only (see 5.0, 6.0)
B48: Jacket
B49: Wing added on EACH side, B direction | C49: eB | D49: 600 | E49: mm | F49: 0 = no enlargement in this direction
B50: Wing added on EACH side, L direction | C50: eL | D50: 600 | E50: mm
B51: Bonded overlay thickness on top | C51: t,top | D51: 200 | E51: mm | F51: 0 = none; the wings are cast to the full depth h0 + t,top
B52: Jacket concrete strength | C52: f'cj | D52: 28 | E52: MPa
B53: Jacket reinforcement yield | C53: fyj | D53: 415 | E53: MPa
B54: New bottom bars parallel to L | C54: n | D54: 8 | F54: total in the two side wings, continuous over L
B55: Their diameter | C55: db | D55: 20 | E55: mm
B56: New bottom bars parallel to B | C56: n | D56: 10 | F56: total in the two end wings, continuous over B
B57: Their diameter | C57: db | D57: 20 | E57: mm
B58: Clear cover to the new outer layer | C58: ccj | D58: 75 | E58: mm
B59: Lightweight concrete factor | C59: lambda | D59: 1
B60: Interfaces
B61: Surface of the old concrete | D61: roughened | F61: roughened = ~6 mm amplitude, ACI 318-25M 26.5.6.2(e); ACI 562-25 9.4.4.3
...

Sheet Theory
D1: D E S I G N S H E E T
D2: Project : | E2: =IF('Footing Jacket'!$E$2="","",'Footing Jacket'!$E$2) -> Project name
D3: Member : | E3: =IF('Footing Jacket'!$E$3="","",'Footing Jacket'!$E$3) -> F-1 - Grid A-1
D4: Designed / Date : | E4: =IF('Footing Jacket'!$E$4="","",'Footing Jacket'!$E$4) -> Albert Pamonag | G4: =IF('Footing Jacket'!$G$4="","",'Footing Jacket'!$G$4) -> 46299
D5: Checked / Date : | E5: =IF('Footing Jacket'!$E$5="","",'Footing Jacket'!$E$5) | G5: =IF('Footing Jacket'!$G$5="","",'Footing Jacket'!$G$5)
B6: THEORETICAL REFERENCE - FOOTING JACKET
B7: ACI 562-25; ACI 318-25M; ASCE 41-17 - clause and printed page under each card
B8: Reference sheet - no inputs. Every cell and picture is locked. Owner: Albert Pamonag - Albert Pamonag Engineering Consultancy.
B10: Equations and provisions behind the calculation sheet
B11: Each card sets out, in this sheet's own notation, the equations a section of the calculation sheet uses; the line under it gives the clause and the printed page where the provision is found. The cards are typeset for this workbook - they are not copies of the standards, which remain the authority.
B13: A. LOAD HISTORY AND BEARING PRESSURE
B28: Basis: ACI 562-25 R9.4.1 (p. 85) and R9.2.1 (p. 84); ASCE 41-17 C8.7 item 2 (p. 455); ACI 318-25M 13.3.1.1 (p. 211).
B30: B. PRESSURE BEYOND A SECTION
B44: Basis: Statics. Critical sections: ACI 318-25M Table 13.2.7.1 and 13.2.7.2 (p. 210), 7.4.3.2 (p. 101).
B46: C. FLEXURE OF THE COMPOSITE SECTION
B59: Basis: ACI 318-25M 22.3.3.2 to 22.3.3.4 (p. 440), Table 22.2.2.4.3 (p. 439), 7.6.1.1 (p. 102), 8.6.1.1 (p. 122), 13.3.1.2 (p. 212); ACI 562-25 Table 5.3.2 (p. 38).
B61: D. ONE-WAY SHEAR
... B132: (c) Albert Pamonag Engineering Consultancy. Owner: Albert Pamonag. This calculation sheet is protected; the engineer of record remains responsible for the inputs and for the checks listed as not covered.
